<?xml version="1.0"?>
<robot xmlns:xacro="http://www.ros.org/wiki/xacro" name="simple_car">

  <!-- Inertial Macros -->
  <xacro:macro name="box_inertia" params="m x y z">
    <inertial>
      <mass value="${m}"/>
      <inertia ixx="${m*(y*y+z*z)/12}" ixy="0" ixz="0"
               iyy="${m*(x*x+z*z)/12}" iyz="0"
               izz="${m*(x*x+y*y)/12}"/>
    </inertial>
  </xacro:macro>

  <xacro:macro name="cylinder_inertia" params="m r h">
    <inertial>
      <mass value="${m}"/>
      <inertia ixx="${m*(3*r*r+h*h)/12}" ixy="0" ixz="0"
               iyy="${m*(3*r*r+h*h)/12}" iyz="0"
               izz="${m*r*r/2}"/>
    </inertial>
  </xacro:macro>

  <!-- Base Link -->
  <link name="base_link">
    <visual>
      <geometry>
        <box size="0.5 0.3 0.1"/>
      </geometry>
      <material name="blue">
        <color rgba="0 0 1 1"/>
      </material>
    </visual>
    <collision>
      <geometry>
        <box size="0.5 0.3 0.1"/>
      </geometry>
    </collision>
    <xacro:box_inertia m="5.0" x="0.5" y="0.3" z="0.1"/>
  </link>

  <!-- Wheels -->
  <xacro:macro name="wheel" params="name x y">
    <link name="${name}_wheel">
      <visual>
        <geometry>
          <cylinder radius="0.1" length="0.05"/>
        </geometry>
        <material name="black">
          <color rgba="0 0 0 1"/>
        </material>
      </visual>
      <collision>
        <geometry>
          <cylinder radius="0.1" length="0.05"/>
        </geometry>
        <surface>
          <friction>
            <ode>
              <mu>0.5</mu>
              <mu2>0.5</mu2>
            </ode>
          </friction>
        </surface>
      </collision>
      <xacro:cylinder_inertia m="1.0" r="0.1" h="0.05"/>
    </link>

    <joint name="${name}_wheel_joint" type="continuous">
      <parent link="base_link"/>
      <child link="${name}_wheel"/>
      <origin xyz="${x} ${y} -0.05" rpy="-1.5707 0 0"/>
      <axis xyz="0 0 1"/>
    </joint>
  </xacro:macro>

  <!-- Increased y offset to avoid collision with base_link (0.15 + 0.025 + gap) -->
  <xacro:wheel name="front_left" x="0.15" y="0.2"/>
  <xacro:wheel name="front_right" x="0.15" y="-0.2"/>
  <xacro:wheel name="rear_left" x="-0.15" y="0.2"/>
  <xacro:wheel name="rear_right" x="-0.15" y="-0.2"/>

  <!-- Gazebo Plugin for Diff Drive (Skid Steer style) -->
  <gazebo>
    <plugin filename="ignition-gazebo-diff-drive-system" name="ignition::gazebo::systems::DiffDrive">
      <left_joint>front_left_wheel_joint</left_joint>
      <left_joint>rear_left_wheel_joint</left_joint>
      <right_joint>front_right_wheel_joint</right_joint>
      <right_joint>rear_right_wheel_joint</right_joint>
      <wheel_separation>0.4</wheel_separation>
      <wheel_radius>0.1</wheel_radius>
      <odom_publish_frequency>20</odom_publish_frequency>
      <topic>cmd_vel</topic>
      <odom_topic>odom</odom_topic>
      <tf_topic>tf</tf_topic>
      <frame_id>odom</frame_id>
      <child_frame_id>base_link</child_frame_id>
    </plugin>
    
    <!-- Joint State Publisher -->
    <plugin filename="ignition-gazebo-joint-state-publisher-system" name="ignition::gazebo::systems::JointStatePublisher">
    </plugin>
  </gazebo>

</robot>
